<?xml version="1.0"?>

<robot name="basic">

  <link name="robot_footprint"></link>

  <joint name="robot_footprint_joint" type="fixed">
    <parent link="robot_footprint"/>
    <child link="base_link"/>
    <origin xyz="0 0 0.3"/>
  </joint>

  <link name="base_link">
    <visual>
      <geometry>
        <cylinder length="0.6" radius="0.2"/>
      </geometry>
      <origin rpy="0 0 0" xyz="0 0 0"/>
    </visual>
  </link>

  <link name="right_leg">
    <visual>
      <geometry>
        <box size="0.6 0.1 0.2"/>
      </geometry>
      <origin rpy="0 1.57075 0" xyz="0 -0.03 -0.3"/>
    </visual>
  </link>

  <joint name="right_leg_joint" type="continuous">
    <axis xyz="0 1 0"/>
    <parent link="base_link"/>
    <child link="right_leg"/>
    <origin xyz="0 -0.22 0.25"/>
  </joint>

</robot>
